Traceback (most recent call last):
  File "/Users/yuchiaol_ntuas/miniconda3/lib/python3.11/site-packages/nbclient/client.py", line 778, in _async_poll_for_reply
    msg = await ensure_async(self.kc.shell_channel.get_msg(timeout=new_timeout))
          ^^^^^^^^^^^^^^^^^^^^^^^^^^^^^^^^^^^^^^^^^^^^^^^^^^^^^^^^^^^^^^^^^^^^^^
  File "/Users/yuchiaol_ntuas/miniconda3/lib/python3.11/site-packages/jupyter_core/utils/__init__.py", line 182, in ensure_async
    result = await obj
             ^^^^^^^^^
  File "/Users/yuchiaol_ntuas/miniconda3/lib/python3.11/site-packages/jupyter_client/channels.py", line 315, in get_msg
    raise Empty
_queue.Empty

During handling of the above exception, another exception occurred:

Traceback (most recent call last):
  File "/Users/yuchiaol_ntuas/miniconda3/lib/python3.11/site-packages/jupyter_cache/executors/utils.py", line 58, in single_nb_execution
    executenb(
  File "/Users/yuchiaol_ntuas/miniconda3/lib/python3.11/site-packages/nbclient/client.py", line 1305, in execute
    return NotebookClient(nb=nb, resources=resources, km=km, **kwargs).execute()
           ^^^^^^^^^^^^^^^^^^^^^^^^^^^^^^^^^^^^^^^^^^^^^^^^^^^^^^^^^^^^^^^^^^^^^
  File "/Users/yuchiaol_ntuas/miniconda3/lib/python3.11/site-packages/jupyter_core/utils/__init__.py", line 166, in wrapped
    return loop.run_until_complete(inner)
           ^^^^^^^^^^^^^^^^^^^^^^^^^^^^^^
  File "/Users/yuchiaol_ntuas/miniconda3/lib/python3.11/asyncio/base_events.py", line 653, in run_until_complete
    return future.result()
           ^^^^^^^^^^^^^^^
  File "/Users/yuchiaol_ntuas/miniconda3/lib/python3.11/site-packages/nbclient/client.py", line 705, in async_execute
    await self.async_execute_cell(
  File "/Users/yuchiaol_ntuas/miniconda3/lib/python3.11/site-packages/nbclient/client.py", line 1001, in async_execute_cell
    exec_reply = await self.task_poll_for_reply
                 ^^^^^^^^^^^^^^^^^^^^^^^^^^^^^^
  File "/Users/yuchiaol_ntuas/miniconda3/lib/python3.11/site-packages/nbclient/client.py", line 802, in _async_poll_for_reply
    error_on_timeout_execute_reply = await self._async_handle_timeout(timeout, cell)
                                     ^^^^^^^^^^^^^^^^^^^^^^^^^^^^^^^^^^^^^^^^^^^^^^^
  File "/Users/yuchiaol_ntuas/miniconda3/lib/python3.11/site-packages/nbclient/client.py", line 852, in _async_handle_timeout
    raise CellTimeoutError.error_from_timeout_and_cell(
nbclient.exceptions.CellTimeoutError: A cell timed out while it was being executed, after 30 seconds.
The message was: Cell execution timed out.
Here is a preview of the cell contents:
-------------------
['model4 = climlab.process_like(model2)  # initialize with cold Snowball temperature', "model4.subprocess['insolation'].S0 = 1830.", 'model4.integrate_years(40)', 'plt.plot(model4.lat, model4.Ts)', "plt.xlim(-90,90); plt.ylabel('Temperature (Â°C)'); plt.xlabel('Latitude')"]
...
["ax.set_ylabel('Ice edge latitude', fontsize=16)", "ax.set_xlabel('Solar constant (W m$^{-2}$)', fontsize=16)", "ax.plot( [const.S0, const.S0], [-10, 100], 'k--', label='present-day' )", "ax.legend(loc='upper left')", "ax.set_title('Solar constant versus ice edge latitude in the EBM with albedo feedback', fontsize=16);"]
-------------------

