Traceback (most recent call last):
  File "/Users/yuchiaol_ntuas/miniconda3/lib/python3.11/site-packages/jupyter_cache/executors/utils.py", line 58, in single_nb_execution
    executenb(
  File "/Users/yuchiaol_ntuas/miniconda3/lib/python3.11/site-packages/nbclient/client.py", line 1305, in execute
    return NotebookClient(nb=nb, resources=resources, km=km, **kwargs).execute()
           ^^^^^^^^^^^^^^^^^^^^^^^^^^^^^^^^^^^^^^^^^^^^^^^^^^^^^^^^^^^^^^^^^^^^^
  File "/Users/yuchiaol_ntuas/miniconda3/lib/python3.11/site-packages/jupyter_core/utils/__init__.py", line 166, in wrapped
    return loop.run_until_complete(inner)
           ^^^^^^^^^^^^^^^^^^^^^^^^^^^^^^
  File "/Users/yuchiaol_ntuas/miniconda3/lib/python3.11/asyncio/base_events.py", line 653, in run_until_complete
    return future.result()
           ^^^^^^^^^^^^^^^
  File "/Users/yuchiaol_ntuas/miniconda3/lib/python3.11/site-packages/nbclient/client.py", line 705, in async_execute
    await self.async_execute_cell(
  File "/Users/yuchiaol_ntuas/miniconda3/lib/python3.11/site-packages/nbclient/client.py", line 1058, in async_execute_cell
    await self._check_raise_for_error(cell, cell_index, exec_reply)
  File "/Users/yuchiaol_ntuas/miniconda3/lib/python3.11/site-packages/nbclient/client.py", line 914, in _check_raise_for_error
    raise CellExecutionError.from_cell_and_msg(cell, exec_reply_content)
nbclient.exceptions.CellExecutionError: An error occurred while executing the following cell:
------------------
import xarray as xr
import pandas as pd
import numpy as np
from matplotlib import pyplot as plt
import sklearn
import sklearn.ensemble
import scipy.stats
from sklearn.model_selection import train_test_split
from tqdm import tqdm
import xarray as xr
import pandas as pd
import numpy as np
from matplotlib import pyplot as plt
import sklearn
import sklearn.ensemble
import scipy.stats
from sklearn.model_selection import train_test_split
import torch
#import torchvision
import torch.nn as nn
import torch.nn.functional as F
import torch.optim as optim
from torch.utils.data import Dataset, DataLoader
from scipy.stats import pearsonr
from sklearn.metrics import mean_squared_error
------------------


[0;31m---------------------------------------------------------------------------[0m
[0;31mModuleNotFoundError[0m                       Traceback (most recent call last)
Cell [0;32mIn[1], line 5[0m
[1;32m      3[0m [38;5;28;01mimport[39;00m [38;5;21;01mnumpy[39;00m [38;5;28;01mas[39;00m [38;5;21;01mnp[39;00m
[1;32m      4[0m [38;5;28;01mfrom[39;00m [38;5;21;01mmatplotlib[39;00m [38;5;28;01mimport[39;00m pyplot [38;5;28;01mas[39;00m plt
[0;32m----> 5[0m [38;5;28;01mimport[39;00m [38;5;21;01msklearn[39;00m
[1;32m      6[0m [38;5;28;01mimport[39;00m [38;5;21;01msklearn[39;00m[38;5;21;01m.[39;00m[38;5;21;01mensemble[39;00m
[1;32m      7[0m [38;5;28;01mimport[39;00m [38;5;21;01mscipy[39;00m[38;5;21;01m.[39;00m[38;5;21;01mstats[39;00m

[0;31mModuleNotFoundError[0m: No module named 'sklearn'

